Workbook

Sheet 1_Cadastramento
A1: Dados iniciais
A2: Insira o nome dos professores | C2: Insira o nome das turmas (por exemplo: 7 Ano A) | D2: Turno | F2: Insira o nome das disciplinas (por exemplo: matemática) | H2: Insira os todos os intervalos | I2: Recreio ou almoço/jantar?
A3: ACT- MTM | C3: 11 | D3: Matutino | F3: Arte | H3: Entre a 3ª e 4ª aula | I3: Recreio
A4: ACT_EM | C4: 12 | D4: Matutino | F4: Ciên | H4: Entre a 5ª e 6ª aula | I4: Almoço
A5: ACT_PLE | C5: 13 | D5: Vespertino | F5: Ed.Fís | H5: Entre a 8ª e 9ª aula | I5: Recreio
A6: ACT_PORT | C6: 21 | D6: Matutino | F6: Geo
A7: ACT_HIST1 | C7: 22 | D7: Vespertino | F7: His
A8: ACT_HIST2 | C8: 23 | D8: Integral | F8: Ing
A9: ADELIDIO | C9: 31 | D9: Matutino | F9: Lab.Ciê
A10: AGNES | C10: 32 | D10: Matutino | F10: Mat
A11: ALINE | C11: 33 | D11: Vespertino | F11: Port
A12: ANA LUCIA | C12: 41 | D12: Matutino | F12: Regencia
A13: ANA LUIZA | C13: 42 | D13: Vespertino | F13: Tecn
A14: AUX_LET | C14: 43 | D14: Vespertino | F14: Arte2
A15: AUX_NUM | C15: 51 | D15: Integral | F15: LET
A16: CAMILA | C16: 52 | D16: Integral | F16: NUM
A17: CHRISTELLE | C17: 53 | D17: Integral | F17: SUS
... A19: DELSON | C19: 62 | D19: Vespertino | F19: PLE
A20: DOUGLAS | C20: 63 | D20: Vespertino
A21: EDILMA | C21: 71 | D21: Matutino
A22: EDUARDO | C22: 72 | D22: Matutino
A23: EMANUELE | C23: 73 | D23: Vespertino
A24: FABIANO | C24: 81 | D24: Matutino
A25: FERNANDA | C25: 82 | D25: Vespertino
A26: GIANE | C26: 83 | D26: Vespertino
A27: GRAYCE | C27: 91 | D27: Matutino
A28: GREYCE | C28: 92 | D28: Matutino
A29: GUSTAVO | C29: 93 | D29: Vespertino
A30: HELENA
A31: JULIANE
A32: LOELIA
A33: MARIA LUIZA
A34: MARIANA
A35: MAURA
A36: PRISCILA
A37: SAMANTA
A38: SIMONE
A39: TAINA
A40: THIAGO
A41: TUANI
...

Sheet Planilha1
A1: 11 Maria Luiza | B1: 12 Emanuelle | C1: 21 Giane | D1: 23 Simone | E1: 31 Mariana | F1: 32 Vanderlane | G1: 41 Samantha | H1: 51 Ana Lucia | I1: 52 Grayce | J1: 53 Tuani | K1: 13 Maria Luiza | L1: 22 Giane | M1: 33 Vanderlane | N1: 42 Cintia | O1: 43 Tainá | P1: 61 | Q1: 71 | R1: 72 | S1: 81 | T1: 91 | U1: 92 | V1: 62 | W1: 63 | X1: 73 | Y1: 82 | Z1: 83 | AA1: 93
A2: 11 Maria Luiza | B2: 12 Emanuelle | C2: 21 Giane | D2: 23 Simone | E2: 31 Mariana | F2: 32 Vanderlane | G2: 41 Samantha | H2: 51 Ana Lucia | I2: 52 Grayce | J2: 53 Tuani | K2: 13 Maria Luiza | L2: 22 Giane | M2: 33 Vanderlane | N2: 42 Cintia | O2: 43 Tainá | P2: 61 | Q2: 71 | R2: 72 | S2: 81 | T2: 91 | U2: 92 | V2: 62 | W2: 63 | X2: 73 | Y2: 82 | Z2: 83 | AA2: 93
A3: 11 Maria Luiza | B3: 12 Emanuelle | C3: 21 Giane | D3: 23 Simone | E3: 31 Mariana | F3: 32 Vanderlane | G3: 41 Samantha | H3: 51 Ana Lucia | I3: 52 Grayce | J3: 53 Tuani | K3: 13 Maria Luiza | L3: 22 Giane | M3: 33 Vanderlane | N3: 42 Cintia | O3: 43 Tainá | P3: 61 | Q3: 71 | R3: 72 | S3: 81 | T3: 91 | U3: 92 | V3: 62 | W3: 63 | X3: 73 | Y3: 82 | Z3: 83 | AA3: 93
A4: 11 Maria Luiza | B4: 12 Emanuelle | C4: 21 Giane | D4: 23 Simone | E4: 31 Mariana | F4: 32 Vanderlane | G4: 41 Samantha | H4: 51 Ana Lucia | I4: 52 Grayce | J4: 53 Tuani | K4: 13 Maria Luiza | L4: 22 Giane | M4: 33 Vanderlane | N4: 42 Cintia | O4: 43 Tainá | P4: 61 | Q4: 71 | R4: 72 | S4: 81 | T4: 91 | U4: 92 | V4: 62 | W4: 63 | X4: 73 | Y4: 82 | Z4: 83 | AA4: 93
A5: 11 Maria Luiza | B5: 12 Emanuelle | C5: 21 Giane | D5: 23 Simone | E5: 31 Mariana | F5: 32 Vanderlane | G5: 41 Samantha | H5: 51 Ana Lucia | I5: 52 Grayce | J5: 53 Tuani | K5: 13 Maria Luiza | L5: 22 Giane | M5: 33 Vanderlane | N5: 42 Cintia | O5: 43 Tainá | P5: 61 | Q5: 71 | R5: 72 | S5: 81 | T5: 91 | U5: 92 | V5: 62 | W5: 63 | X5: 73 | Y5: 82 | Z5: 83 | AA5: 93
A6: Greyce(Tecn) | B6: Ana Luiza(Arte) | C6: Douglas(Ing) | D6: Priscila(Ed.Fís) | E6: Regente | F6: Helena(Ing) | G6: Regente | H6: Loelia(Arte) | I6: Eduardo(Ed.Fís) | J6: Delson(Tecn) | K6: Douglas(Ing) | L6: Regente | M6: Priscila(Ed.Fís) | N6: Regente | O6: Camila(Ing) | P6: ACT(His) | Q6: Christelle(Ing) | R6: Viviane(Ciên) | S6: Adelidio(Geo) | T6: Gustavo(Geo) | U6: Aline(Port) | V6: Juliane(Ciên) | W6: Aline(Port) | X6: Loelia(Arte) | Y6: Helena(Port) | Z6: Fabiano(Ed.Fís) | AA6: Gustavo(Geo)
A7: Priscila(Ed.Fís) | B7: Ana Luiza(Arte) | C7: Regente | D7: Regente | E7: Regente | F7: Regente | G7: Regente | H7: Christelle(Ing) | I7: Delson(Tecn) | J7: Loelia(Arte) | K7: Priscila(Ed.Fís) | L7: Regente | M7: Regente | N7: Regente | O7: Regente | P7: Eduardo(Ed.Fís) | Q7: Viviane(Ciên) | R7: ACT(His) | S7: Helena(Port) | T7: Juliane(Ciên) | U7: Aline(Port) | V7: Loelia(Arte) | W7: Adelidio(Geo) | X7: ACT(His) | Y7: Helena(Port) | Z7: Fabiano(Ed.Fís) | AA7: Juliane(Ciên)
A8: Ana Luiza(Arte) | B8: Douglas(Ing) | C8: Regente | D8: Regente | E8: Regente | F8: Regente | G8: Regente | H8: Christelle(Ing) | I8: Delson(Tecn) | J8: Edilma(Lab.Ciê) | K8: Greyce(Tecn) | L8: Priscila(Ed.Fís) | M8: Regente | N8: Regente | O8: Regente | P8: Loelia(Arte) | Q8: ACT(His) | R8: Agnes(Port) | S8: Helena(Port) | T8: Aline(Port) | U8: Gustavo(Geo) | V8: Adelidio(Geo) | W8: Fabiano(Ed.Fís) | X8: ACT(His) | Y8: Viviane(Ciên) | Z8: Helena(Port) | AA8: Juliane(Ciên)
A9: Ana Luiza(Arte) | B9: Douglas(Ing) | C9: Regente | D9: Regente | E9: Regente | F9: Regente | G9: Regente | H9: Eduardo(Ed.Fís) | I9: Loelia(Arte) | J9: Edilma(Lab.Ciê) | K9: Greyce(Tecn) | L9: Priscila(Ed.Fís) | M9: Regente | N9: Regente | O9: Regente | P9: Adelidio(Geo) | Q9: ACT(His) | R9: Agnes(Port) | S9: Christelle(Ing) | T9: Aline(Port) | U9: Gustavo(Geo) | V9: ACT(His) | W9: Fabiano(Ed.Fís) | X9: Juliane(Ciên) | Y9: Viviane(Ciên) | Z9: Helena(Port) | AA9: Aline(Port)
A10: Priscila(Ed.Fís) | B10: Greyce(Tecn) | C10: Regente | D10: Regente | E10: Regente | F10: Regente | G10: Regente | H10: Fernanda(EM) | I10: Loelia(Arte) | J10: Regente | K10: Regente | L10: Regente | M10: Greyce(Tecn) | N10: Regente | O10: Regente | P10: Maura(Mat) | Q10: Adelidio(Geo) | R10: Fabiano(Ed.Fís) | S10: ACT(Mat) | T10: Juliane(Ciên) | U10: Ana Luiza(Arte) | V10: Adelidio(Geo) | W10: ACT(His) | X10: Maura(Mat) | Y10: ACT(Mat) | Z10: Ana Luiza(Arte) | AA10: Fernanda(Mat)
A11: Priscila(Ed.Fís) | B11: Greyce(Tecn) | C11: Regente | D11: Regente | E11: Regente | F11: Regente | G11: Regente | H11: Regente | I11: Loelia(Arte) | J11: Regente | K11: Regente | L11: Regente | M11: Greyce(Tecn) | N11: Regente | O11: Regente | P11: Maura(Mat) | Q11: Adelidio(Geo) | R11: Fabiano(Ed.Fís) | S11: ACT(Mat) | T11: Juliane(Ciên) | U11: Ana Luiza(Arte) | V11: Adelidio(Geo) | W11: ACT(His) | X11: Maura(Mat) | Y11: ACT(Mat) | Z11: Ana Luiza(Arte) | AA11: Juliane(Ciên)
A12: Greyce(Tecn) | B12: Priscila(Ed.Fís) | C12: Douglas(Ing) | D12: Regente | E12: Regente | F12: Ana Luiza(Arte) | G12: Regente | H12: Loelia(Arte) | I12: Eduardo(Ed.Fís) | J12: Delson(Tecn) | K12: Douglas(Ing) | L12: Regente | M12: Priscila(Ed.Fís) | N12: Regente | O12: Camila(Ing) | P12: ACT(His) | Q12: Christelle(Ing) | R12: Viviane(Ciên) | S12: Adelidio(Geo) | T12: Gustavo(Geo) | U12: Juliane(Ciên) | V12: Juliane(Ciên) | W12: Aline(Port) | X12: Loelia(Arte) | Y12: Fabiano(Ed.Fís) | Z12: Adelidio(Geo) | AA12: Gustavo(Geo)
A13: Regente | B13: Priscila(Ed.Fís) | C13: Greyce(Tecn) | D13: Vinicius(Arte) | E13: Ana Luiza(Arte) | F13: Regente | G13: Helena(Ing) | H13: Regente | I13: Eduardo(Ed.Fís) | J13: Regente | K13: Priscila(Ed.Fís) | L13: Tiago(Ing) | M13: Regente | N13: Greyce(Tecn) | O13: Vinicius(Arte) | P13: Christelle(Ing) | Q13: Loelia(Arte) | R13: ACT(His) | S13: Fabiano(Ed.Fís) | T13: Aline(Port) | U13: Fernanda(Mat) | V13: Eduardo(Ed.Fís) | W13: Maura(Mat) | X13: Agnes(Port) | Y13: Helena(Port) | Z13: Juliane(Ciên) | AA13: Fabiano(Ed.Fís)
A14: Regente | B14: Priscila(Ed.Fís) | C14: Greyce(Tecn) | D14: Vinicius(Arte) | E14: Ana Luiza(Arte) | F14: Regente | G14: Helena(Ing) | H14: Regente | I14: Eduardo(Ed.Fís) | J14: Regente | K14: Priscila(Ed.Fís) | L14: Tiago(Ing) | M14: Regente | N14: Greyce(Tecn) | O14: Vinicius(Arte) | P14: Christelle(Ing) | Q14: Loelia(Arte) | R14: ACT(His) | S14: Adelidio(Geo) | T14: Aline(Port) | U14: Fernanda(Mat) | V14: Eduardo(Ed.Fís) | W14: Maura(Mat) | X14: Agnes(Port) | Y14: Helena(Port) | Z14: Juliane(Ciên) | AA14: Fabiano(Ed.Fís)
A15: Helena(Ing) | B15: Regente | C15: Regente | D15: Regente | E15: Greyce(Tecn) | F15: Priscila(Ed.Fís) | G15: Regente | H15: Regente | I15: Regente | J15: Regente | K15: Regente | L15: Regente | M15: Priscila(Ed.Fís) | N15: Camila(Ing) | O15: Eduardo(Ed.Fís) | P15: Juliane(Ciên) | Q15: Fabiano(Ed.Fís) | R15: Vinicius(Arte) | S15: Viviane(Ciên) | T15: Fernanda(Mat) | U15: Aline(Port) | V15: Loelia(Arte) | W15: Juliane(Ciên) | X15: Maura(Mat) | Y15: Ana Luiza(Arte) | Z15: Fabiano(Ed.Fís) | AA15: Aline(Port)
A16: Helena(Ing) | B16: Regente | C16: Regente | D16: Regente | E16: Greyce(Tecn) | F16: Priscila(Ed.Fís) | G16: Regente | H16: Regente | I16: Regente | J16: Regente | K16: Regente | L16: Regente | M16: Ana Luiza(Arte) | N16: Camila(Ing) | O16: Eduardo(Ed.Fís) | P16: Juliane(Ciên) | Q16: Agnes(Port) | R16: Vinicius(Arte) | S16: Viviane(Ciên) | T16: Fernanda(Mat) | U16: Aline(Port) | V16: Loelia(Arte) | W16: Juliane(Ciên) | X16: Maura(Mat) | Y16: Fabiano(Ed.Fís) | Z16: Tiago(Ing) | AA16: Aline(Port)
A17: Regente | B17: Regente | C17: Regente | D17: Regente | E17: Regente | F17: Regente | G17: Regente | H17: Regente | I17: Regente | J17: Regente | K17: Regente | L17: Regente | M17: Regente | N17: Eduardo(Ed.Fís) | O17: Regente | P17: Eduardo(Ed.Fís) | Q17: Maura(Mat) | R17: Agnes(Port) | S17: Helena(Port) | T17: Christelle(Ing) | U17: Fernanda(Mat) | V17: ACT(His) | W17: Tiago(Ing) | X17: Christelle(Ing) | Y17: ACT(Mat) | Z17: Adelidio(Geo) | AA17: Aline(Port)
... A30: Regente | B30: Regente | C30: Regente | D30: Regente | E30: Regente | F30: Regente | G30: Regente | H30: Regente | I30: Regente | J30: Regente | K30: Regente | L30: Regente | M30: Regente | N30: Regente | O30: Regente | P30: Adelidio(Geo) | Q30: Loelia(Arte) | R30: Viviane(Ciên) | S30: Fabiano(Ed.Fís) | T30: Fernanda(Mat) | U30: Juliane(Ciên) | V30: Maura(Mat) | W30: Adelidio(Geo) | X30: Fabiano(Ed.Fís) | Y30: Ana Luiza(Arte) | Z30: ACT(His) | AA30: Fernanda(Mat)
D31: 23 Simone | H31: 51 Ana Lucia | I31: 52 Grayce | J31: 53 Tuani
D32: Regente | H32: Delson(Tecn) | I32: Regente | J32: Helena(PLE)
D33: Regente | H33: Delson(Tecn) | I33: Regente | J33: Helena(PLE)
D34: Regente | H34: Regente | I34: Regente | J34: Regente
D35: Delson(Tecn) | H35: Regente | I35: Regente | J35: Regente
D36: Delson(Tecn) | H36: Regente | I36: Regente | J36: Regente
D37: 23 Simone | H37: 51 Ana Lucia | I37: 52 Grayce | J37: 53 Tuani
D38: Priscila(Ed.Fís) | H38: Agnes(PLE) | I38: Fernanda(EM) | J38: Regente
D39: Tiago(Ing) | H39: Agnes(PLE) | I39: Regente | J39: Helena(PLE)
D40: Tiago(Ing) | H40: Regente | I40: Regente | J40: Regente
D41: Loelia(Arte) | H41: Regente | I41: Regente | J41: Regente
D42: Loelia(Arte) | H42: Regente | I42: Regente | J42: Regente
... D60: Regente | H60: Edilma(Lab.Ciê) | I60: Vinicius(Arte) | J60: Regente

Sheet 2_disciplinasXturmas
A1: Instrução: Na célula relativa à disciplina/turma, insira a carga horária semanal.
A2: disciplinas/turmas | B2: {=TRANSPOSE(IF('1_Cadastramento'!C3:C104="","",'1_Cadastramento'!C3:C104))} -> 11 | C2: 12 | D2: 13 | E2: 21 | F2: 22 | G2: 23 | H2: 31 | I2: 32 | J2: 33 | K2: 41 | L2: 42 | M2: 43 | N2: 51 | O2: 52 | P2: 53 | Q2: 61 | R2: 62 | S2: 63 | T2: 71 | U2: 72 | V2: 73 | W2: 81 | X2: 82 | Y2: 83 | Z2: 91 | AA2: 92 | AB2: 93
A3: {=IF('1_Cadastramento'!F3:F104="","",'1_Cadastramento'!F3:F104)} -> Arte | B3: 2 | C3: 2 | D3: 2 | E3: 2 | F3: 2 | G3: 3 | H3: 2 | I3: 2 | J3: 2 | K3: 2 | L3: 2 | M3: 2 | N3: 3 | O3: 3 | P3: 3 | Q3: 3 | R3: 3 | S3: 3 | T3: 3 | U3: 3 | V3: 3 | W3: 2 | X3: 2 | Y3: 2 | Z3: 2 | AA3: 2 | AB3: 2
A4: Ciên | Q4: 3 | R4: 3 | S4: 3 | T4: 3 | U4: 3 | V4: 3 | W4: 4 | X4: 4 | Y4: 4 | Z4: 3 | AA4: 3 | AB4: 3
A5: Ed.Fís | B5: 3 | C5: 3 | D5: 3 | E5: 3 | F5: 3 | G5: 4 | H5: 3 | I5: 3 | J5: 3 | K5: 3 | L5: 3 | M5: 3 | N5: 4 | O5: 4 | P5: 4 | Q5: 3 | R5: 3 | S5: 3 | T5: 3 | U5: 3 | V5: 3 | W5: 3 | X5: 3 | Y5: 3 | Z5: 2 | AA5: 2 | AB5: 2
A6: Geo | Q6: 3 | R6: 3 | S6: 3 | T6: 3 | U6: 3 | V6: 3 | W6: 3 | X6: 3 | Y6: 3 | Z6: 2 | AA6: 2 | AB6: 2
A7: His | Q7: 3 | R7: 3 | S7: 3 | T7: 3 | U7: 3 | V7: 3 | W7: 3 | X7: 3 | Y7: 3 | Z7: 2 | AA7: 2 | AB7: 2
A8: Ing | B8: 2 | C8: 2 | D8: 2 | E8: 2 | F8: 2 | G8: 4 | H8: 2 | I8: 2 | J8: 2 | K8: 2 | L8: 2 | M8: 2 | N8: 4 | O8: 4 | P8: 4 | Q8: 2 | R8: 2 | S8: 2 | T8: 2 | U8: 2 | V8: 2 | W8: 2 | X8: 2 | Y8: 2 | Z8: 2 | AA8: 2 | AB8: 2
A9: Lab.Ciê | G9: 2 | N9: 2 | O9: 2 | P9: 2
A10: Mat | Q10: 4 | R10: 4 | S10: 4 | T10: 4 | U10: 4 | V10: 4 | W10: 4 | X10: 4 | Y10: 4 | Z10: 6 | AA10: 6 | AB10: 6
A11: Port | Q11: 4 | R11: 4 | S11: 4 | T11: 4 | U11: 4 | V11: 4 | W11: 4 | X11: 4 | Y11: 4 | Z11: 6 | AA11: 6 | AB11: 6
A12: Regencia | B12: 16 | C12: 16 | D12: 16 | E12: 16 | F12: 16 | G12: 32 | H12: 16 | I12: 16 | J12: 16 | K12: 16 | L12: 16 | M12: 16 | N12: 32 | O12: 32 | P12: 32
A13: Tecn | B13: 2 | C13: 2 | D13: 2 | E13: 2 | F13: 2 | G13: 2 | H13: 2 | I13: 2 | J13: 2 | K13: 2 | L13: 2 | M13: 2 | N13: 2 | O13: 2 | P13: 2
A14: Arte2 | G14: 3 | N14: 3 | O14: 3 | P14: 3
A15: LET | G15: 3
A16: NUM | G16: 3
A17: SUS | G17: 3 | N17: 3 | O17: 3 | P17: 3
A18: EM | N18: 3 | O18: 3 | P18: 3
A19: PLE | N19: 3 | O19: 3 | P19: 3

Sheet 3_professorXdisciplinas
A1: Intrução: selecione o professor que ministra cada disciplina em cada turma.
A2: Disciplinas | B2: {=TRANSPOSE(IF('1_Cadastramento'!C3:C104="","",'1_Cadastramento'!C3:C104))} -> 11 | C2: 12 | D2: 13 | E2: 21 | F2: 22 | G2: 23 | H2: 31 | I2: 32 | J2: 33 | K2: 41 | L2: 42 | M2: 43 | N2: 51 | O2: 52 | P2: 53 | Q2: 61 | R2: 62 | S2: 63 | T2: 71 | U2: 72 | V2: 73 | W2: 81 | X2: 82 | Y2: 83 | Z2: 91 | AA2: 92 | AB2: 93
A3: {=IF('1_Cadastramento'!F3:F104="","",'1_Cadastramento'!F3:F104)} -> Arte | B3: ANA LUIZA | C3: ANA LUIZA | D3: ANA LUIZA | E3: ANA LUIZA | F3: ANA LUIZA | G3: LOELIA | H3: ANA LUIZA | I3: ANA LUIZA | J3: ANA LUIZA | K3: VINICIUS | L3: VINICIUS | M3: VINICIUS | N3: LOELIA | O3: LOELIA | P3: LOELIA | Q3: LOELIA | R3: LOELIA | S3: LOELIA | T3: LOELIA | U3: VINICIUS | V3: LOELIA | W3: ANA LUIZA | X3: ANA LUIZA | Y3: ANA LUIZA | Z3: ANA LUIZA | AA3: ANA LUIZA | AB3: ANA LUIZA
A4: Ciên | Q4: JULIANE | R4: JULIANE | S4: JULIANE | T4: VIVIANE | U4: VIVIANE | V4: JULIANE | W4: VIVIANE | X4: VIVIANE | Y4: JULIANE | Z4: JULIANE | AA4: JULIANE | AB4: JULIANE
A5: Ed.Fís | B5: PRISCILA | C5: PRISCILA | D5: PRISCILA | E5: PRISCILA | F5: PRISCILA | G5: PRISCILA | H5: PRISCILA | I5: PRISCILA | J5: PRISCILA | K5: EDUARDO | L5: EDUARDO | M5: EDUARDO | N5: EDUARDO | O5: EDUARDO | P5: EDUARDO | Q5: EDUARDO | R5: EDUARDO | S5: FABIANO | T5: FABIANO | U5: FABIANO | V5: FABIANO | W5: FABIANO | X5: FABIANO | Y5: FABIANO | Z5: FABIANO | AA5: FABIANO | AB5: FABIANO
A6: Geo | Q6: ADELIDIO | R6: ADELIDIO | S6: ADELIDIO | T6: ADELIDIO | U6: ADELIDIO | V6: ADELIDIO | W6: ADELIDIO | X6: ADELIDIO | Y6: ADELIDIO | Z6: GUSTAVO | AA6: GUSTAVO | AB6: GUSTAVO
A7: His | Q7: ACT_HIST1 | R7: ACT_HIST1 | S7: ACT_HIST1 | T7: ACT_HIST1 | U7: ACT_HIST1 | V7: ACT_HIST1 | W7: ACT_HIST1 | X7: ACT_HIST1 | Y7: ACT_HIST1 | Z7: ACT_HIST2 | AA7: ACT_HIST2 | AB7: ACT_HIST2
A8: Ing | B8: HELENA | C8: DOUGLAS | D8: DOUGLAS | E8: DOUGLAS | F8: THIAGO | G8: THIAGO | H8: HELENA | I8: HELENA | J8: CAMILA | K8: HELENA | L8: CAMILA | M8: CAMILA | N8: CHRISTELLE | O8: CHRISTELLE | P8: CHRISTELLE | Q8: CHRISTELLE | R8: THIAGO | S8: THIAGO | T8: CHRISTELLE | U8: CHRISTELLE | V8: CHRISTELLE | W8: CHRISTELLE | X8: THIAGO | Y8: THIAGO | Z8: CHRISTELLE | AA8: CHRISTELLE | AB8: CHRISTELLE
A9: Lab.Ciê | G9: EDILMA | N9: EDILMA | O9: EDILMA | P9: EDILMA
A10: Mat | Q10: MAURA | R10: MAURA | S10: MAURA | T10: MAURA | U10: MAURA | V10: MAURA | W10: FERNANDA | X10: FERNANDA | Y10: ACT- MTM | Z10: FERNANDA | AA10: FERNANDA | AB10: FERNANDA
A11: Port | Q11: AGNES | R11: ALINE | S11: ALINE | T11: AGNES | U11: AGNES | V11: ACT_PORT | W11: HELENA | X11: HELENA | Y11: HELENA | Z11: ALINE | AA11: ALINE | AB11: ALINE
A12: Regencia | B12: MARIA LUIZA | C12: EMANUELE | D12: MARIA LUIZA | E12: GIANE | F12: GIANE | G12: SIMONE | H12: MARIANA | I12: VANDERLANE | J12: VANDERLANE | K12: SAMANTA | L12: CINTIA | M12: TAINA | N12: ANA LUCIA | O12: GRAYCE | P12: TUANI
A13: Tecn | B13: GREYCE | C13: GREYCE | D13: GREYCE | E13: GREYCE | F13: GREYCE | G13: DELSON | H13: GREYCE | I13: GREYCE | J13: GREYCE | K13: GREYCE | L13: GREYCE | M13: GREYCE | N13: DELSON | O13: DELSON | P13: DELSON
A14: Arte2 | G14: VINICIUS | N14: VINICIUS | O14: VINICIUS | P14: VINICIUS
A15: LET | G15: AUX_LET
A16: NUM | G16: AUX_NUM
A17: SUS | G17: VIVIANE | N17: VIVIANE | O17: VIVIANE | P17: VIVIANE
A18: EM | N18: ACT_EM | O18: ACT_EM | P18: ACT_EM
A19: PLE | N19: ACT_PLE | O19: HELENA | P19: HELENA
A103: =IF('1_Cadastramento'!$F$103="","",'1_Cadastramento'!$F$103)

Sheet 4_qtd_aulas
A1: Insira a qtd de aulas que cada turma tem em cada dia da semana
A2: Dia da semana | B2: {=TRANSPOSE(IF('1_Cadastramento'!C3:C104="","",'1_Cadastramento'!C3:C104))} -> 11 | C2: 12 | D2: 13 | E2: 21 | F2: 22 | G2: 23 | H2: 31 | I2: 32 | J2: 33 | K2: 41 | L2: 42 | M2: 43 | N2: 51 | O2: 52 | P2: 53 | Q2: 61 | R2: 62 | S2: 63 | T2: 71 | U2: 72 | V2: 73 | W2: 81 | X2: 82 | Y2: 83 | Z2: 91 | AA2: 92 | AB2: 93
A3: Segunda-feira | B3: 5 | C3: 5 | D3: 5 | E3: 5 | F3: 5 | G3: 10 | H3: 5 | I3: 5 | J3: 5 | K3: 5 | L3: 5 | M3: 5 | N3: 10 | O3: 10 | P3: 10 | Q3: 5 | R3: 5 | S3: 5 | T3: 5 | U3: 5 | V3: 5 | W3: 5 | X3: 5 | Y3: 5 | Z3: 5 | AA3: 5 | AB3: 5
A4: Terça-feira | B4: 5 | C4: 5 | D4: 5 | E4: 5 | F4: 5 | G4: 10 | H4: 5 | I4: 5 | J4: 5 | K4: 5 | L4: 5 | M4: 5 | N4: 10 | O4: 10 | P4: 10 | Q4: 5 | R4: 5 | S4: 5 | T4: 5 | U4: 5 | V4: 5 | W4: 5 | X4: 5 | Y4: 5 | Z4: 5 | AA4: 5 | AB4: 5
A5: Quarta-feira | B5: 5 | C5: 5 | D5: 5 | E5: 5 | F5: 5 | G5: 10 | H5: 5 | I5: 5 | J5: 5 | K5: 5 | L5: 5 | M5: 5 | N5: 10 | O5: 10 | P5: 10 | Q5: 5 | R5: 5 | S5: 5 | T5: 5 | U5: 5 | V5: 5 | W5: 5 | X5: 5 | Y5: 5 | Z5: 5 | AA5: 5 | AB5: 5
A6: Quinta-feira | B6: 5 | C6: 5 | D6: 5 | E6: 5 | F6: 5 | G6: 10 | H6: 5 | I6: 5 | J6: 5 | K6: 5 | L6: 5 | M6: 5 | N6: 10 | O6: 10 | P6: 10 | Q6: 5 | R6: 5 | S6: 5 | T6: 5 | U6: 5 | V6: 5 | W6: 5 | X6: 5 | Y6: 5 | Z6: 5 | AA6: 5 | AB6: 5
A7: Sexta-feira | B7: 5 | C7: 5 | D7: 5 | E7: 5 | F7: 5 | G7: 10 | H7: 5 | I7: 5 | J7: 5 | K7: 5 | L7: 5 | M7: 5 | N7: 10 | O7: 10 | P7: 10 | Q7: 5 | R7: 5 | S7: 5 | T7: 5 | U7: 5 | V7: 5 | W7: 5 | X7: 5 | Y7: 5 | Z7: 5 | AA7: 5 | AB7: 5
A8: Sábado | B8: 0 | C8: 0 | D8: 0 | E8: 0 | F8: 0 | G8: 0 | H8: 0 | I8: 0 | J8: 0 | K8: 0 | L8: 0 | M8: 0 | N8: 0 | O8: 0 | P8: 0 | Q8: 0 | R8: 0 | S8: 0 | T8: 0 | U8: 0 | V8: 0 | W8: 0 | X8: 0 | Y8: 0 | Z8: 0 | AA8: 0 | AB8: 0
A9: Domingo | B9: 0 | C9: 0 | D9: 0 | E9: 0 | F9: 0 | G9: 0 | H9: 0 | I9: 0 | J9: 0 | K9: 0 | L9: 0 | M9: 0 | N9: 0 | O9: 0 | P9: 0 | Q9: 0 | R9: 0 | S9: 0 | T9: 0 | U9: 0 | V9: 0 | W9: 0 | X9: 0 | Y9: 0 | Z9: 0 | AA9: 0 | AB9: 0

Sheet 5_folga
A1: Indique, numa escala de 0 a 2, a preferência por vir trabalhar. Entenda o "0" como a impossibildade de vir, "2" como sendo a preferência máxima de trabalhar nesse dia e "1" como indiferente.
B2: Segunda-feira | E2: Terça-feira | H2: Quarta-feira | K2: Quinta-feira | N2: Sexta-feira | Q2: =IF(SUM('4_qtd_aulas'!B8:CX8)=0,"","Sábado") | T2: =IF(SUM('4_qtd_aulas'!B9:CX9)=0,"","Domingo")
A3: Nomes | B3: Turno 1 | C3: Turno 2 | D3: Turno 3 | E3: Turno 1 | F3: Turno 2 | G3: Turno 3 | H3: Turno 1 | I3: Turno 2 | J3: Turno 3 | K3: Turno 1 | L3: Turno 2 | M3: Turno 3 | N3: Turno 1 | O3: Turno 2 | P3: Turno 3 | Q3: =IF(SUM('4_qtd_aulas'!B8:CX8)=0,"","Turno 1") | R3: =IF(SUM('4_qtd_aulas'!B8:CX8)=0,"","Turno 2") | S3: =IF(SUM('4_qtd_aulas'!B8:CX8)=0,"","Turno 3") | T3: =IF(SUM('4_qtd_aulas'!B9:CX9)=0,"","Turno 1") | U3: =IF(SUM('4_qtd_aulas'!B9:CX9)=0,"","Turno 2") | V3: =IF(SUM('4_qtd_aulas'!B9:CX9)=0,"","Turno 3")
A4: {=IF('1_Cadastramento'!A3:A104="","",'1_Cadastramento'!A3:A104)} -> ACT- MTM | B4: 1 | C4: 1 | E4: 1 | F4: 1 | H4: 1 | I4: 1 | K4: 1 | L4: 1 | N4: 1 | O4: 1
A5: ACT_EM | B5: 1 | C5: 1 | E5: 1 | F5: 1 | H5: 1 | I5: 1 | K5: 1 | L5: 1 | N5: 1 | O5: 1
A6: ACT_PLE | B6: 1 | C6: 1 | E6: 1 | F6: 1 | H6: 1 | I6: 1 | K6: 1 | L6: 1 | N6: 1 | O6: 1
A7: ACT_PORT | B7: 1 | C7: 1 | E7: 1 | F7: 1 | H7: 1 | I7: 1 | K7: 1 | L7: 1 | N7: 1 | O7: 1
A8: ACT_HIST1 | B8: 1 | C8: 1 | E8: 1 | F8: 1 | H8: 1 | I8: 1 | K8: 1 | L8: 1 | N8: 1 | O8: 1
A9: ACT_HIST2 | B9: 1 | C9: 1 | E9: 1 | F9: 1 | H9: 1 | I9: 1 | K9: 1 | L9: 1 | N9: 1 | O9: 1
A10: ADELIDIO | B10: 1 | C10: 1 | E10: 1 | F10: 1 | H10: 1 | I10: 1 | K10: 1 | L10: 1 | N10: 1 | O10: 1
A11: AGNES | B11: 1 | C11: 1 | E11: 1 | F11: 1 | H11: 1 | I11: 1 | K11: 1 | L11: 1 | N11: 1 | O11: 1
A12: ALINE | B12: 1 | C12: 1 | E12: 1 | F12: 1 | H12: 1 | I12: 1 | K12: 1 | L12: 1 | N12: 1 | O12: 1
A13: ANA LUCIA | B13: 1 | C13: 1 | E13: 1 | F13: 1 | H13: 1 | I13: 1 | K13: 1 | L13: 1 | N13: 1 | O13: 1
A14: ANA LUIZA | B14: 1 | C14: 1 | E14: 1 | F14: 1 | H14: 1 | I14: 1 | K14: 1 | L14: 1 | N14: 1 | O14: 1
A15: AUX_LET | B15: 1 | C15: 1 | E15: 1 | F15: 1 | H15: 1 | I15: 1 | K15: 1 | L15: 1 | N15: 1 | O15: 1
A16: AUX_NUM | B16: 1 | C16: 1 | E16: 1 | F16: 1 | H16: 1 | I16: 1 | K16: 1 | L16: 1 | N16: 1 | O16: 1
... A45: VIVIANE | B45: 1 | C45: 1 | E45: 1 | F45: 1 | H45: 1 | I45: 1 | K45: 1 | L45: 1 | N45: 1 | O45: 1
A104: =IF('1_Cadastramento'!$A$103="","",'1_Cadastramento'!$A$103)

Sheet 6_preferencias
A1: Preferências: Sim, Não ou Indiferente
A2: Nomes | B2: Prefere ministrar 1° aula? | C2: Prefere ministrar ultima aula? | D2: Aula dupla
A3: {=IF('1_Cadastramento'!$A$3:A104="","",'1_Cadastramento'!$A$3:A104)} -> ACT- MTM | B3: Indiferente | C3: Indiferente | D3: Indiferente
A4: ACT_EM | B4: Indiferente | C4: Indiferente | D4: Indiferente
A5: ACT_PLE | B5: Indiferente | C5: Indiferente | D5: Indiferente
A6: ACT_PORT | B6: Indiferente | C6: Indiferente | D6: Indiferente
A7: ACT_HIST1 | B7: Indiferente | C7: Indiferente | D7: Indiferente
A8: ACT_HIST2 | B8: Indiferente | C8: Indiferente | D8: Indiferente
A9: ADELIDIO | B9: Indiferente | C9: Indiferente | D9: Indiferente
A10: AGNES | B10: Indiferente | C10: Indiferente | D10: Indiferente
A11: ALINE | B11: Indiferente | C11: Indiferente | D11: Indiferente
A12: ANA LUCIA | B12: Indiferente | C12: Indiferente | D12: Indiferente
A13: ANA LUIZA | B13: Indiferente | C13: Indiferente | D13: Indiferente
A14: AUX_LET | B14: Indiferente | C14: Indiferente | D14: Indiferente
A15: AUX_NUM | B15: Indiferente | C15: Indiferente | D15: Indiferente
... A44: VIVIANE | B44: Indiferente | C44: Indiferente | D44: Indiferente
A103: =IF('1_Cadastramento'!$A$103="","",'1_Cadastramento'!$A$103)

Sheet 7_restricoes_pontuais
A1: Imposição | F1: Proibição
A2: Professor | B2: Turma | C2: Dia | D2: Horário | E2: Disciplina | F2: Professor | G2: Turma | H2: Dia | I2: Horário | J2: Disciplina
A3: ADALGIZA | B3: 6° A | C3: Segunda-feira | D3: 7ª aula | E3: ESTUDO ORIENTADO E AVALIAÇÃO SEMANAL - EF | F3: DANILO | G3: Todas | H3: Todos | I3: 6ª aula | J3: Todas
A4: ADALGIZA | B4: 6° A | C4: Segunda-feira | D4: 8ª aula | E4: ESTUDO ORIENTADO E AVALIAÇÃO SEMANAL - EF | F4: ALESSANDRA | G4: Todas | H4: Sexta-feira | I4: Todas | J4: Todas
A5: ADALGIZA | B5: 6° A | C5: Segunda-feira | D5: 9ª aula | E5: ESTUDO ORIENTADO E AVALIAÇÃO SEMANAL - EF
A6: PAULA | B6: 6° B | C6: Segunda-feira | D6: 7ª aula | E6: ESTUDO ORIENTADO E AVALIAÇÃO SEMANAL - EF
A7: PAULA | B7: 6° B | C7: Segunda-feira | D7: 8ª aula | E7: ESTUDO ORIENTADO E AVALIAÇÃO SEMANAL - EF
A8: PAULA | B8: 6° B | C8: Segunda-feira | D8: 9ª aula | E8: ESTUDO ORIENTADO E AVALIAÇÃO SEMANAL - EF
A9: PAMELLA | B9: 7° A | C9: Segunda-feira | D9: 7ª aula | E9: ESTUDO ORIENTADO E AVALIAÇÃO SEMANAL - EF
A10: PAMELLA | B10: 7° A | C10: Segunda-feira | D10: 8ª aula | E10: ESTUDO ORIENTADO E AVALIAÇÃO SEMANAL - EF
A11: PAMELLA | B11: 7° A | C11: Segunda-feira | D11: 9ª aula | E11: ESTUDO ORIENTADO E AVALIAÇÃO SEMANAL - EF
A12: CAMILE | B12: 8° A | C12: Segunda-feira | D12: 7ª aula | E12: ESTUDO ORIENTADO E AVALIAÇÃO SEMANAL - EF
A13: CAMILE | B13: 8° A | C13: Segunda-feira | D13: 8ª aula | E13: ESTUDO ORIENTADO E AVALIAÇÃO SEMANAL - EF
A14: CAMILE | B14: 8° A | C14: Segunda-feira | D14: 9ª aula | E14: ESTUDO ORIENTADO E AVALIAÇÃO SEMANAL - EF
A15: SÔNIA | B15: 8° B | C15: Segunda-feira | D15: 7ª aula | E15: ESTUDO ORIENTADO E AVALIAÇÃO SEMANAL - EF
A16: SÔNIA | B16: 8° B | C16: Segunda-feira | D16: 8ª aula | E16: ESTUDO ORIENTADO E AVALIAÇÃO SEMANAL - EF
... A52: ALESSANDRA | B52: 3° A | C52: Quinta-feira | D52: 5ª aula | E52: ELETIVA DE BASE

Sheet formularios
A1: Aulas da disciplina na turma | B1: Peso da preferencia | C1: Sim/Não | D1: Todos | E1: - | F1: Todas | H1: 0 | J1: Todos | K1: Todas | L1: Todas
B2: 0 | C2: Sim | D2: {=IFERROR(INDEX(E:E, SMALL(IF(E:E<>"", ROW(E:E)), ROW(E2))),"")} -> Segunda-feira | E2: =IF('5_folga'!B2="","","Segunda-feira") -> Segunda-feira | F2: =IF($G$2>=1,"1ª aula","") -> 1ª aula | G2: =MAX('4_qtd_aulas'!B3:K9) -> 10 | H2: 1 | I2: Entre a 1ª e 2ª aula | J2: =IF('1_Cadastramento'!$A$3="","",'1_Cadastramento'!$A$3) -> ACT- MTM | K2: =IF('1_Cadastramento'!#REF!="","",'1_Cadastramento'!#REF!) -> #ERROR! | L2: =IF('1_Cadastramento'!#REF!="","",'1_Cadastramento'!#REF!) -> #ERROR!
A3: 0 | B3: 1 | C3: Não | D3: {=IFERROR(INDEX(E:E, SMALL(IF(E:E<>"", ROW(E:E)), ROW(E3))),"")} -> Terça-feira | E3: =IF('5_folga'!E2="","","Terça-feira") -> Terça-feira | F3: =IF($G$2>=2,"2ª aula","") -> 2ª aula | H3: 2 | I3: Entre a 2ª e 3ª aula | J3: =IF('1_Cadastramento'!$A$4="","",'1_Cadastramento'!$A$4) -> ACT_EM | K3: =IF('1_Cadastramento'!#REF!="","",'1_Cadastramento'!#REF!) -> #ERROR! | L3: =IF('1_Cadastramento'!#REF!="","",'1_Cadastramento'!#REF!) -> #ERROR!
A4: 1 | B4: 2 | C4: Indiferente | D4: {=IFERROR(INDEX(E:E, SMALL(IF(E:E<>"", ROW(E:E)), ROW(E4))),"")} -> Quarta-feira | E4: =IF('5_folga'!H2="","","Quarta-feira") -> Quarta-feira | F4: =IF($G$2>=3,"3ª aula","") -> 3ª aula | H4: 3 | I4: Entre a 3ª e 4ª aula | J4: =IF('1_Cadastramento'!$A$5="","",'1_Cadastramento'!$A$5) -> ACT_PLE | K4: =IF('1_Cadastramento'!#REF!="","",'1_Cadastramento'!#REF!) -> #ERROR! | L4: =IF('1_Cadastramento'!#REF!="","",'1_Cadastramento'!#REF!) -> #ERROR!
A5: 2 | D5: {=IFERROR(INDEX(E:E, SMALL(IF(E:E<>"", ROW(E:E)), ROW(E5))),"")} -> Quinta-feira | E5: =IF('5_folga'!K2="","","Quinta-feira") -> Quinta-feira | F5: =IF($G$2>=4,"4ª aula","") -> 4ª aula | H5: 4 | I5: Entre a 4ª e 5ª aula | J5: =IF('1_Cadastramento'!$A$6="","",'1_Cadastramento'!$A$6) -> ACT_PORT | K5: =IF('1_Cadastramento'!#REF!="","",'1_Cadastramento'!#REF!) -> #ERROR! | L5: =IF('1_Cadastramento'!#REF!="","",'1_Cadastramento'!#REF!) -> #ERROR!
A6: 3 | D6: {=IFERROR(INDEX(E:E, SMALL(IF(E:E<>"", ROW(E:E)), ROW(E6))),"")} -> Sexta-feira | E6: =IF('5_folga'!N2="","","Sexta-feira") -> Sexta-feira | F6: =IF($G$2>=5,"5ª aula","") -> 5ª aula | H6: 5 | I6: Entre a 5ª e 6ª aula | J6: =IF('1_Cadastramento'!$A$7="","",'1_Cadastramento'!$A$7) -> ACT_HIST1 | K6: =IF('1_Cadastramento'!#REF!="","",'1_Cadastramento'!#REF!) -> #ERROR! | L6: =IF('1_Cadastramento'!#REF!="","",'1_Cadastramento'!#REF!) -> #ERROR!
A7: 4 | D7: {=IFERROR(INDEX(E:E, SMALL(IF(E:E<>"", ROW(E:E)), ROW(E7))),"")} | E7: =IF('5_folga'!Q2="","","Sábado") | F7: =IF($G$2>=6,"6ª aula","") -> 6ª aula | H7: 6 | I7: Entre a 6ª e 7ª aula | J7: =IF('1_Cadastramento'!$A$8="","",'1_Cadastramento'!$A$8) -> ACT_HIST2 | K7: =IF('1_Cadastramento'!#REF!="","",'1_Cadastramento'!#REF!) -> #ERROR! | L7: =IF('1_Cadastramento'!#REF!="","",'1_Cadastramento'!#REF!) -> #ERROR!
A8: 5 | D8: {=IFERROR(INDEX(E:E, SMALL(IF(E:E<>"", ROW(E:E)), ROW(E8))),"")} | E8: =IF('5_folga'!T2="","","Domingo") | F8: =IF($G$2>=7,"7ª aula","") -> 7ª aula | H8: 7 | I8: Entre a 7ª e 8ª aula | J8: =IF('1_Cadastramento'!$A$9="","",'1_Cadastramento'!$A$9) -> ADELIDIO | K8: =IF('1_Cadastramento'!#REF!="","",'1_Cadastramento'!#REF!) -> #ERROR! | L8: =IF('1_Cadastramento'!#REF!="","",'1_Cadastramento'!#REF!) -> #ERROR!
A9: 6 | F9: =IF($G$2>=8,"8ª aula","") -> 8ª aula | H9: 8 | I9: Entre a 8ª e 9ª aula | J9: =IF('1_Cadastramento'!$A$10="","",'1_Cadastramento'!$A$10) -> AGNES | K9: =IF('1_Cadastramento'!#REF!="","",'1_Cadastramento'!#REF!) -> #ERROR! | L9: =IF('1_Cadastramento'!#REF!="","",'1_Cadastramento'!#REF!) -> #ERROR!
A10: 7 | F10: =IF($G$2>=9,"9ª aula","") -> 9ª aula | H10: 9 | I10: Entre a 9ª e 10ª aula | J10: =IF('1_Cadastramento'!$A$11="","",'1_Cadastramento'!$A$11) -> ALINE | K10: =IF('1_Cadastramento'!#REF!="","",'1_Cadastramento'!#REF!) -> #ERROR! | L10: =IF('1_Cadastramento'!#REF!="","",'1_Cadastramento'!#REF!) -> #ERROR!
A11: 8 | F11: =IF($G$2>=10,"10ª aula","") -> 10ª aula | H11: 10 | I11: Entre a 10ª e 11ª aula | J11: =IF('1_Cadastramento'!$A$12="","",'1_Cadastramento'!$A$12) -> ANA LUCIA | K11: =IF('1_Cadastramento'!#REF!="","",'1_Cadastramento'!#REF!) -> #ERROR! | L11: =IF('1_Cadastramento'!#REF!="","",'1_Cadastramento'!#REF!) -> #ERROR!
A12: 9 | F12: =IF($G$2>=11,"11ª aula","") | I12: Entre a 11ª e 12ª aula | J12: =IF('1_Cadastramento'!$A$13="","",'1_Cadastramento'!$A$13) -> ANA LUIZA | K12: =IF('1_Cadastramento'!#REF!="","",'1_Cadastramento'!#REF!) -> #ERROR! | L12: =IF('1_Cadastramento'!#REF!="","",'1_Cadastramento'!#REF!) -> #ERROR!
A13: 10 | F13: =IF($G$2>=12,"12ª aula","") | I13: Entre a 12ª e 13ª aula | J13: =IF('1_Cadastramento'!$A$14="","",'1_Cadastramento'!$A$14) -> AUX_LET | K13: =IF('1_Cadastramento'!#REF!="","",'1_Cadastramento'!#REF!) -> #ERROR! | L13: =IF('1_Cadastramento'!#REF!="","",'1_Cadastramento'!#REF!) -> #ERROR!
A14: 11 | F14: =IF($G$2>=13,"13ª aula","") | I14: Entre a 13ª e 14ª aula | J14: =IF('1_Cadastramento'!$A$15="","",'1_Cadastramento'!$A$15) -> AUX_NUM | K14: =IF('1_Cadastramento'!#REF!="","",'1_Cadastramento'!#REF!) -> #ERROR! | L14: =IF('1_Cadastramento'!#REF!="","",'1_Cadastramento'!#REF!) -> #ERROR!
A15: 12 | F15: =IF($G$2>=14,"14ª aula","") | I15: Entre a 14ª e 15ª aula | J15: =IF('1_Cadastramento'!$A$16="","",'1_Cadastramento'!$A$16) -> CAMILA | K15: =IF('1_Cadastramento'!#REF!="","",'1_Cadastramento'!#REF!) -> #ERROR! | L15: =IF('1_Cadastramento'!$F$14="","",'1_Cadastramento'!$F$14) -> Arte2
A16: 13 | F16: =IF($G$2>=15,"15ª aula","") | I16: Entre a 15ª e 16ª aula | J16: =IF('1_Cadastramento'!$A$17="","",'1_Cadastramento'!$A$17) -> CHRISTELLE | K16: =IF('1_Cadastramento'!#REF!="","",'1_Cadastramento'!#REF!) -> #ERROR! | L16: =IF('1_Cadastramento'!$F$15="","",'1_Cadastramento'!$F$15) -> LET
A17: 14 | F17: =IF($G$2>=16,"16ª aula","") | I17: Não tem | J17: =IF('1_Cadastramento'!$A$18="","",'1_Cadastramento'!$A$18) -> CINTIA | K17: =IF('1_Cadastramento'!#REF!="","",'1_Cadastramento'!#REF!) -> #ERROR! | L17: =IF('1_Cadastramento'!$F$16="","",'1_Cadastramento'!$F$16) -> NUM
A18: 15 | F18: =IF($G$2>=17,"17ª aula","") | J18: =IF('1_Cadastramento'!$A$19="","",'1_Cadastramento'!$A$19) -> DELSON | K18: =IF('1_Cadastramento'!#REF!="","",'1_Cadastramento'!#REF!) -> #ERROR! | L18: =IF('1_Cadastramento'!$F$17="","",'1_Cadastramento'!$F$17) -> SUS
A19: 16 | F19: =IF($G$2>=18,"18ª aula","") | J19: =IF('1_Cadastramento'!$A$20="","",'1_Cadastramento'!$A$20) -> DOUGLAS | K19: =IF('1_Cadastramento'!#REF!="","",'1_Cadastramento'!#REF!) -> #ERROR! | L19: =IF('1_Cadastramento'!$F$18="","",'1_Cadastramento'!$F$18) -> EM
A20: 17 | J20: =IF('1_Cadastramento'!$A$21="","",'1_Cadastramento'!$A$21) -> EDILMA | K20: =IF('1_Cadastramento'!#REF!="","",'1_Cadastramento'!#REF!) -> #ERROR! | L20: =IF('1_Cadastramento'!$F$19="","",'1_Cadastramento'!$F$19) -> PLE
A21: 18 | J21: =IF('1_Cadastramento'!$A$22="","",'1_Cadastramento'!$A$22) -> EDUARDO | K21: =IF('1_Cadastramento'!#REF!="","",'1_Cadastramento'!#REF!) -> #ERROR! | L21: =IF('1_Cadastramento'!$F$22="","",'1_Cadastramento'!$F$22)
A22: 19 | J22: =IF('1_Cadastramento'!$A$23="","",'1_Cadastramento'!$A$23) -> EMANUELE | K22: =IF('1_Cadastramento'!#REF!="","",'1_Cadastramento'!#REF!) -> #ERROR! | L22: =IF('1_Cadastramento'!$F$23="","",'1_Cadastramento'!$F$23)
A23: 20 | J23: =IF('1_Cadastramento'!$A$24="","",'1_Cadastramento'!$A$24) -> FABIANO | K23: =IF('1_Cadastramento'!#REF!="","",'1_Cadastramento'!#REF!) -> #ERROR! | L23: =IF('1_Cadastramento'!$F$24="","",'1_Cadastramento'!$F$24)
A24: 21 | J24: =IF('1_Cadastramento'!$A$25="","",'1_Cadastramento'!$A$25) -> FERNANDA | K24: =IF('1_Cadastramento'!#REF!="","",'1_Cadastramento'!#REF!) -> #ERROR! | L24: =IF('1_Cadastramento'!$F$25="","",'1_Cadastramento'!$F$25)
A25: 22 | J25: =IF('1_Cadastramento'!$A$26="","",'1_Cadastramento'!$A$26) -> GIANE | K25: =IF('1_Cadastramento'!#REF!="","",'1_Cadastramento'!#REF!) -> #ERROR! | L25: =IF('1_Cadastramento'!$F$26="","",'1_Cadastramento'!$F$26)
A26: 23 | J26: =IF('1_Cadastramento'!$A$27="","",'1_Cadastramento'!$A$27) -> GRAYCE | K26: =IF('1_Cadastramento'!$C$23="","",'1_Cadastramento'!$C$23) -> 73 | L26: =IF('1_Cadastramento'!$F$27="","",'1_Cadastramento'!$F$27)
A27: 24 | J27: =IF('1_Cadastramento'!$A$28="","",'1_Cadastramento'!$A$28) -> GREYCE | K27: =IF('1_Cadastramento'!$C$24="","",'1_Cadastramento'!$C$24) -> 81 | L27: =IF('1_Cadastramento'!$F$28="","",'1_Cadastramento'!$F$28)
A28: 25 | J28: =IF('1_Cadastramento'!$A$29="","",'1_Cadastramento'!$A$29) -> GUSTAVO | K28: =IF('1_Cadastramento'!$C$25="","",'1_Cadastramento'!$C$25) -> 82 | L28: =IF('1_Cadastramento'!$F$29="","",'1_Cadastramento'!$F$29)
A29: 26 | J29: =IF('1_Cadastramento'!$A$30="","",'1_Cadastramento'!$A$30) -> HELENA | K29: =IF('1_Cadastramento'!$C$26="","",'1_Cadastramento'!$C$26) -> 83 | L29: =IF('1_Cadastramento'!$F$30="","",'1_Cadastramento'!$F$30)
A30: 27 | J30: =IF('1_Cadastramento'!$A$31="","",'1_Cadastramento'!$A$31) -> JULIANE | K30: =IF('1_Cadastramento'!$C$27="","",'1_Cadastramento'!$C$27) -> 91 | L30: =IF('1_Cadastramento'!$F$31="","",'1_Cadastramento'!$F$31)
J31: =IF('1_Cadastramento'!$A$32="","",'1_Cadastramento'!$A$32) -> LOELIA | K31: =IF('1_Cadastramento'!$C$28="","",'1_Cadastramento'!$C$28) -> 92 | L31: =IF('1_Cadastramento'!$F$32="","",'1_Cadastramento'!$F$32)
J32: =IF('1_Cadastramento'!$A$33="","",'1_Cadastramento'!$A$33) -> MARIA LUIZA | K32: =IF('1_Cadastramento'!$C$29="","",'1_Cadastramento'!$C$29) -> 93 | L32: =IF('1_Cadastramento'!$F$33="","",'1_Cadastramento'!$F$33)
J33: =IF('1_Cadastramento'!$A$34="","",'1_Cadastramento'!$A$34) -> MARIANA | K33: =IF('1_Cadastramento'!$C$34="","",'1_Cadastramento'!$C$34) | L33: =IF('1_Cadastramento'!$F$34="","",'1_Cadastramento'!$F$34)
J34: =IF('1_Cadastramento'!$A$35="","",'1_Cadastramento'!$A$35) -> MAURA | K34: =IF('1_Cadastramento'!$C$35="","",'1_Cadastramento'!$C$35) | L34: =IF('1_Cadastramento'!$F$35="","",'1_Cadastramento'!$F$35)
J35: =IF('1_Cadastramento'!$A$36="","",'1_Cadastramento'!$A$36) -> PRISCILA | K35: =IF('1_Cadastramento'!$C$36="","",'1_Cadastramento'!$C$36) | L35: =IF('1_Cadastramento'!$F$36="","",'1_Cadastramento'!$F$36)
J36: =IF('1_Cadastramento'!$A$37="","",'1_Cadastramento'!$A$37) -> SAMANTA | K36: =IF('1_Cadastramento'!$C$37="","",'1_Cadastramento'!$C$37) | L36: =IF('1_Cadastramento'!$F$37="","",'1_Cadastramento'!$F$37)
J37: =IF('1_Cadastramento'!$A$38="","",'1_Cadastramento'!$A$38) -> SIMONE | K37: =IF('1_Cadastramento'!$C$38="","",'1_Cadastramento'!$C$38) | L37: =IF('1_Cadastramento'!$F$38="","",'1_Cadastramento'!$F$38)
J38: =IF('1_Cadastramento'!$A$39="","",'1_Cadastramento'!$A$39) -> TAINA | K38: =IF('1_Cadastramento'!$C$39="","",'1_Cadastramento'!$C$39) | L38: =IF('1_Cadastramento'!$F$39="","",'1_Cadastramento'!$F$39)
J39: =IF('1_Cadastramento'!$A$40="","",'1_Cadastramento'!$A$40) -> THIAGO | K39: =IF('1_Cadastramento'!$C$40="","",'1_Cadastramento'!$C$40) | L39: =IF('1_Cadastramento'!$F$40="","",'1_Cadastramento'!$F$40)
J40: =IF('1_Cadastramento'!$A$41="","",'1_Cadastramento'!$A$41) -> TUANI | K40: =IF('1_Cadastramento'!$C$41="","",'1_Cadastramento'!$C$41) | L40: =IF('1_Cadastramento'!$F$41="","",'1_Cadastramento'!$F$41)
...

Sheet Horário_turmas

Sheet Horário_professor

Sheet Intersecao_disciplinas
A1: Disciplina A | B1: Disciplina B | C1: Aulas em comum
A2: Regencia | B2: LET | C2: 3
A3: Regencia | B3: NUM | C3: 3
A4: Regencia | B4: SUS | C4: 3
A5: Regencia | B5: EM | C5: 3
A6: Regencia | B6: PLE | C6: 3

Sheet _listas
A1: Ciên
A2: Ed.Fís
A3: Geo
A4: His
A5: Ing
A6: Lab.Ciê
A7: Mat
A8: Port
A9: Regencia
A10: Tecn
A11: Arte2
A12: LET
... A16: PLE
